Data sent successfully, but for some reason, record was not created<Fault 1: 'Traceback (most recent call last):\n  File "/usr/lib/python3/dist-packages/odoo/addons/base/controllers/rpc.py", line 69, in xmlrpc_2\n    response = self._xmlrpc(service)\n  File "/usr/lib/python3/dist-packages/odoo/addons/base/controllers/rpc.py", line 49, in _xmlrpc\n    result = dispatch_rpc(service, method, params)\n  File "/usr/lib/python3/dist-packages/odoo/http.py", line 139, in dispatch_rpc\n    result = dispatch(method, params)\n  File "/usr/lib/python3/dist-packages/odoo/service/model.py", line 41, in dispatch\n    res = fn(db, uid, *params)\n  File "/usr/lib/python3/dist-packages/odoo/service/model.py", line 174, in execute_kw\n    return execute(db, uid, obj, method, *args, **kw or {})\n  File "/usr/lib/python3/dist-packages/odoo/service/model.py", line 94, in wrapper\n    return f(dbname, *args, **kwargs)\n  File "/usr/lib/python3/dist-packages/odoo/service/model.py", line 181, in execute\n    res = execute_cr(cr, uid, obj, method, *args, **kw)\n  File "/usr/lib/python3/dist-packages/odoo/service/model.py", line 165, in execute_cr\n    result = odoo.api.call_kw(recs, method, args, kw)\n  File "/usr/lib/python3/dist-packages/odoo/api.py", line 385, in call_kw\n    result = _call_kw_model_create(method, model, args, kwargs)\n  File "/usr/lib/python3/dist-packages/odoo/api.py", line 365, in _call_kw_model_create\n    result = method(recs, *args, **kwargs)\n  File "<decorator-gen-200>", line 2, in create\n  File "/usr/lib/python3/dist-packages/odoo/api.py", line 314, in _model_create_single\n    return create(self, arg)\n  File "/usr/lib/python3/dist-packages/odoo/addons/hr_recruitment/models/hr_recruitment.py", line 306, in create\n    return super(Applicant, self).create(vals)\n  File "<decorator-gen-110>", line 2, in create\n  File "/usr/lib/python3/dist-packages/odoo/api.py", line 335, in _model_create_multi\n    return create(self, [arg])\n  File "/usr/lib/python3/dist-packages/odoo/addons/mail/models/mail_thread.py", line 268, in create\n    threads = super(MailThread, self).create(vals_list)\n  File "<decorator-gen-3>", line 2, in create\n  File "/usr/lib/python3/dist-packages/odoo/api.py", line 336, in _model_create_multi\n    return create(self, arg)\n  File "/usr/lib/python3/dist-packages/odoo/models.py", line 3745, in create\n    records = self._create(data_list)\n  File "/usr/lib/python3/dist-packages/odoo/models.py", line 3817, in _create\n    col_val = field.convert_to_column(val, self, stored)\n  File "/usr/lib/python3/dist-packages/odoo/fields.py", line 2230, in convert_to_column\n    value = self.convert_to_cache(value, record)\n  File "/usr/lib/python3/dist-packages/odoo/fields.py", line 2242, in convert_to_cache\n    raise ValueError("Wrong value for %s: %r" % (self, value))\nValueError: Wrong value for hr.applicant.travel: \'Excellent\'\n'>

{
    "job_id": 4,
    "social_status": "widowed",
    "ar_r": 7,
    "ar_w": 7,
    "ar_s": 7,
    "ar_u": 7,
    "ar_o": 7,
    "en_r": 7,
    "en_w": 7,
    "en_s": 7,
    "en_u": 7,
    "en_o": 7,
    "name": "some random fields here",
    "surname": "mfmwovnwo",
    "email_from": "Random email.com",
    "partner_phone": "0777473573",
    "health_status": "very poor",
    "team_work": "excellent",
    "pressure": "excellent",
    "travel": "Excellent",
    "referral_source": "employee",
    "preffered_fow": "technical",
    "preferred_cp": "5 years"
}