Data sent successfully, but for some reason, record was not created<Fault 1: 'Traceback (most recent call last):
  File "/usr/lib/python3/dist-packages/odoo/addons/base/controllers/rpc.py", line 69, in xmlrpc_2
    response = self._xmlrpc(service)
  File "/usr/lib/python3/dist-packages/odoo/addons/base/controllers/rpc.py", line 49, in _xmlrpc
    result = dispatch_rpc(service, method, params)
  File "/usr/lib/python3/dist-packages/odoo/http.py", line 139, in dispatch_rpc
    result = dispatch(method, params)
  File "/usr/lib/python3/dist-packages/odoo/service/model.py", line 41, in dispatch
    res = fn(db, uid, *params)
  File "/usr/lib/python3/dist-packages/odoo/service/model.py", line 174, in execute_kw
    return execute(db, uid, obj, method, *args, **kw or {})
  File "/usr/lib/python3/dist-packages/odoo/service/model.py", line 94, in wrapper
    return f(dbname, *args, **kwargs)
  File "/usr/lib/python3/dist-packages/odoo/service/model.py", line 181, in execute
    res = execute_cr(cr, uid, obj, method, *args, **kw)
  File "/usr/lib/python3/dist-packages/odoo/service/model.py", line 165, in execute_cr
    result = odoo.api.call_kw(recs, method, args, kw)
  File "/usr/lib/python3/dist-packages/odoo/api.py", line 385, in call_kw
    result = _call_kw_model_create(method, model, args, kwargs)
  File "/usr/lib/python3/dist-packages/odoo/api.py", line 365, in _call_kw_model_create
    result = method(recs, *args, **kwargs)
  File "<decorator-gen-200>", line 2, in create
  File "/usr/lib/python3/dist-packages/odoo/api.py", line 314, in _model_create_single
    return create(self, arg)
  File "/usr/lib/python3/dist-packages/odoo/addons/hr_recruitment/models/hr_recruitment.py", line 306, in create
    return super(Applicant, self).create(vals)
  File "<decorator-gen-110>", line 2, in create
  File "/usr/lib/python3/dist-packages/odoo/api.py", line 335, in _model_create_multi
    return create(self, [arg])
  File "/usr/lib/python3/dist-packages/odoo/addons/mail/models/mail_thread.py", line 268, in create
    threads = super(MailThread, self).create(vals_list)
  File "<decorator-gen-3>", line 2, in create
  File "/usr/lib/python3/dist-packages/odoo/api.py", line 336, in _model_create_multi
    return create(self, arg)
  File "/usr/lib/python3/dist-packages/odoo/models.py", line 3745, in create
    records = self._create(data_list)
  File "/usr/lib/python3/dist-packages/odoo/models.py", line 3817, in _create
    col_val = field.convert_to_column(val, self, stored)
  File "/usr/lib/python3/dist-packages/odoo/fields.py", line 2230, in convert_to_column
    value = self.convert_to_cache(value, record)
  File "/usr/lib/python3/dist-packages/odoo/fields.py", line 2242, in convert_to_cache
    raise ValueError("Wrong value for %s: %r" % (self, value))
ValueError: Wrong value for hr.applicant.travel: \'very_good\'
'>

{
    "job_id": 4,
    "social_status": "widowed",
    "ar_r": 7,
    "ar_w": 7,
    "ar_s": 7,
    "ar_u": 7,
    "ar_o": 7,
    "en_r": 7,
    "en_w": 7,
    "en_s": 7,
    "en_u": 7,
    "en_o": 7,
    "name": "some random fields here",
    "surname": "mfmwovnwo",
    "email_from": "Random email.com",
    "partner_phone": "0777473573",
    "health_status": "very poor",
    "team_work": "excellent",
    "pressure": "excellent",
    "travel": "very_good",
    "referral_source": "employee",
    "preffered_fow": "technical",
    "preferred_cp": "5 years"
}